<mujoco model="base">
  <compiler angle="radian" meshdir="meshes/" />
  <option cone="elliptic" impratio="20" />
  <size nconmax="5000" njmax="5000" />
  <visual>
      <map znear="0.001" />
  </visual>

  <asset>
  <texture builtin="flat" height="256" rgb1="1 1 1." rgb2=".2 .3 .4" type="skybox" width="256" />
        <texture builtin="checker" height="512" name="texplane" rgb1=".2 .3 .4" rgb2=".1 0.15 0.2" type="2d" width="512" />
        <material name="floorplane" reflectance="0.5" texrepeat="1 1" texture="texplane" texuniform="true" />
    <mesh file="c:\users\harsh\onedrive - georgia institute of technology\documents\georgia tech\spring 2025\cs 7648 irl\project\furniture\furniture\env\models\assets\robots\sawyer\meshes/pedestal.stl" name="pedestal" />
        <mesh file="c:\users\harsh\onedrive - georgia institute of technology\documents\georgia tech\spring 2025\cs 7648 irl\project\furniture\furniture\env\models\assets\robots\sawyer\meshes/base.stl" name="base" />
        <mesh file="c:\users\harsh\onedrive - georgia institute of technology\documents\georgia tech\spring 2025\cs 7648 irl\project\furniture\furniture\env\models\assets\robots\sawyer\meshes/l0.stl" name="l0" />
        <mesh file="c:\users\harsh\onedrive - georgia institute of technology\documents\georgia tech\spring 2025\cs 7648 irl\project\furniture\furniture\env\models\assets\robots\sawyer\meshes/head.stl" name="head" />
        <mesh file="c:\users\harsh\onedrive - georgia institute of technology\documents\georgia tech\spring 2025\cs 7648 irl\project\furniture\furniture\env\models\assets\robots\sawyer\meshes/l1.stl" name="l1" />
        <mesh file="c:\users\harsh\onedrive - georgia institute of technology\documents\georgia tech\spring 2025\cs 7648 irl\project\furniture\furniture\env\models\assets\robots\sawyer\meshes/l2.stl" name="l2" />
        <mesh file="c:\users\harsh\onedrive - georgia institute of technology\documents\georgia tech\spring 2025\cs 7648 irl\project\furniture\furniture\env\models\assets\robots\sawyer\meshes/l3.stl" name="l3" />
        <mesh file="c:\users\harsh\onedrive - georgia institute of technology\documents\georgia tech\spring 2025\cs 7648 irl\project\furniture\furniture\env\models\assets\robots\sawyer\meshes/l4.stl" name="l4" />
        <mesh file="c:\users\harsh\onedrive - georgia institute of technology\documents\georgia tech\spring 2025\cs 7648 irl\project\furniture\furniture\env\models\assets\robots\sawyer\meshes/l5.stl" name="l5" />
        <mesh file="c:\users\harsh\onedrive - georgia institute of technology\documents\georgia tech\spring 2025\cs 7648 irl\project\furniture\furniture\env\models\assets\robots\sawyer\meshes/l6.stl" name="l6" />
    <mesh file="c:\users\harsh\onedrive - georgia institute of technology\documents\georgia tech\spring 2025\cs 7648 irl\project\furniture\furniture\env\models\assets\grippers\meshes/two_finger_gripper/electric_gripper_base.STL" name="electric_gripper_base" />
        <mesh file="c:\users\harsh\onedrive - georgia institute of technology\documents\georgia tech\spring 2025\cs 7648 irl\project\furniture\furniture\env\models\assets\grippers\meshes/two_finger_gripper/standard_narrow.STL" name="standard_narrow" />
        <mesh file="c:\users\harsh\onedrive - georgia institute of technology\documents\georgia tech\spring 2025\cs 7648 irl\project\furniture\furniture\env\models\assets\grippers\meshes/two_finger_gripper/half_round_tip.STL" name="half_round_tip" />
    <mesh file="c:\users\harsh\onedrive - georgia institute of technology\documents\georgia tech\spring 2025\cs 7648 irl\project\furniture\furniture\env\models\assets\objects\toy_table/0.stl" name="part0" scale="0.042 0.042 0.042" />
    <mesh file="c:\users\harsh\onedrive - georgia institute of technology\documents\georgia tech\spring 2025\cs 7648 irl\project\furniture\furniture\env\models\assets\objects\toy_table/4.stl" name="part4" scale="0.042 0.042 0.042" />
    <mesh file="c:\users\harsh\onedrive - georgia institute of technology\documents\georgia tech\spring 2025\cs 7648 irl\project\furniture\furniture\env\models\assets\objects\toy_table/3.stl" name="part3" scale="0.042 0.042 0.042" />
    <mesh file="c:\users\harsh\onedrive - georgia institute of technology\documents\georgia tech\spring 2025\cs 7648 irl\project\furniture\furniture\env\models\assets\objects\toy_table/2.stl" name="part2" scale="0.042 0.042 0.042" />
    <mesh file="c:\users\harsh\onedrive - georgia institute of technology\documents\georgia tech\spring 2025\cs 7648 irl\project\furniture\furniture\env\models\assets\objects\toy_table/1.stl" name="part1" scale="0.042 0.042 0.042" />
  </asset>

  <actuator>
  <velocity ctrllimited="true" ctrlrange="-1.74 1.74" joint="right_j0" kv="8.0" name="vel_right_j0" />
        <velocity ctrllimited="true" ctrlrange="-1.328 1.328" joint="right_j1" kv="7.0" name="vel_right_j1" />
        <velocity ctrllimited="true" ctrlrange="-1.957 1.957" joint="right_j2" kv="6.0" name="vel_right_j2" />
        <velocity ctrllimited="true" ctrlrange="-1.957 1.957" joint="right_j3" kv="4.0" name="vel_right_j3" />
        <velocity ctrllimited="true" ctrlrange="-3.485 3.485" joint="right_j4" kv="2.0" name="vel_right_j4" />
        <velocity ctrllimited="true" ctrlrange="-3.485 3.485" joint="right_j5" kv="0.5" name="vel_right_j5" />
        <velocity ctrllimited="true" ctrlrange="-4.545 4.545" joint="right_j6" kv="0.1" name="vel_right_j6" />
    <position ctrllimited="true" ctrlrange="-0.020833 0.0115" forcelimited="true" forcerange="-20 20" joint="r_gripper_r_finger_joint" kp="10000" name="gripper_r_gripper_r_finger_joint" />
        <position ctrllimited="true" ctrlrange="-0.0115 0.020833" forcelimited="true" forcerange="-20 20" joint="r_gripper_l_finger_joint" kp="10000" name="gripper_r_gripper_l_finger_joint" />
    </actuator>

  <worldbody>
  <geom condim="3" friction="2.0 0.005 0.0001" name="FLOOR" pos="0 0 0" rgba="0.7 0.7 0.7 1" size="0.75 0.5 0.0625" type="plane" />

        <light castshadow="true" diffuse=".8 .8 .8" dir=".5 -.3 -.8" directional="true" pos="0 0 2.0" specular="0.3 0.3 0.3" />

        
        
        
        <camera fovy="60" mode="fixed" name="frontview" pos="0 -1.2 0.9" quat="0.86 0.51 0. 0." /> 
        <camera mode="fixed" name="sideview" pos="-2.5 0. 0.5" quat="0.5468 0.4482 -0.4482 -0.5468" />
    <body name="base" pos="0.0 0.65 0.21300000000000008" quat="1 0 0 -1">
            <inertial diaginertia="0 0 0" mass="0" pos="0 0 0" />
            <body name="controller_box" pos="0 0 0">
                <inertial diaginertia="1.71363 1.27988 0.809981" mass="46.64" pos="-0.325 0 -0.38" />
                <geom conaffinity="0" contype="0" name="controller_box_visual" pos="-0.325 0 -0.38" size="0.11 0.2 0.265" type="box" />
            </body>
            <body name="pedestal_feet" pos="0 0 0">
                <inertial diaginertia="8.16095 9.59375 15.0785" mass="167.09" pos="-0.1225 0 -0.758" />
                <geom conaffinity="0" contype="0" name="pedestal_feet_visual" pos="-0.1225 0 -0.758" size="0.385 0.35 0.155" type="box" />
            </body>
            <body name="torso" pos="0 0 0">
                <inertial diaginertia="1e-08 1e-08 1e-08" mass="0.0001" pos="0 0 0" />
                <geom conaffinity="0" contype="0" group="1" name="torso_visual" rgba="0.2 0.2 0.2 1" size="0.05 0.05 0.05" type="box" />
            </body>
            <body name="pedestal" pos="0 0 0">
                <inertial diaginertia="6.0869 5.81635 4.20915" mass="60.864" pos="0 0 0" quat="0.659267 -0.259505 -0.260945 0.655692" />
                <geom conaffinity="0" contype="0" group="1" mesh="pedestal" name="pedestal_visual" pos="0.26 0.345 -0.91488" quat="0.5 0.5 -0.5 -0.5" rgba="0.2 0.2 0.2 1" type="mesh" />
                <geom name="pedestal_collision" pos="-0.02 0 -0.29" rgba="0.2 0.2 0.2 1" size="0.18 0.31" type="cylinder" />
            </body>
            <body name="right_arm_base_link" pos="0 0 0">
                <inertial diaginertia="0.00740351 0.00681776 0.00672942" mass="2.0687" pos="-0.0006241 -2.8025e-05 0.065404" quat="-0.209285 0.674441 0.227335 0.670558" />
                <geom conaffinity="0" contype="0" group="1" mesh="base" name="right_arm_base_link_visual" rgba="0.5 0.1 0.1 1" type="mesh" />
                <geom name="right_arm_base_link_collision" pos="0 0 0.12" rgba="0.5 0.1 0.1 1" size="0.08 0.12" type="cylinder" />
                <body name="right_l0" pos="0 0 0.08">
                    <inertial diaginertia="0.0651588 0.0510944 0.0186218" mass="5.3213" pos="0.024366 0.010969 0.14363" quat="0.894823 0.00899958 -0.170275 0.412573" />
                    <joint axis="0 0 1" limited="true" name="right_j0" pos="0 0 0" range="-3.0503 3.0503" />
                    <geom conaffinity="0" contype="0" group="1" mesh="l0" name="right_l0_visual" rgba="0.5 0.1 0.1 1" type="mesh" />
                    <geom name="right_l0_collision" pos="0.08 0 0.23" rgba="0.5 0.1 0.1 1" size="0.07" />
                    <body name="head" pos="0 0 0.2965">
                        <inertial diaginertia="0.0118334 0.00827089 0.00496574" mass="1.5795" pos="0.0053207 -2.6549e-05 0.1021" quat="0.999993 7.08405e-05 -0.00359857 -0.000626247" />
                            
                            <geom conaffinity="0" contype="0" group="1" mesh="head" name="head_visual" rgba="0.5 0.1 0.1 1" type="mesh" />
                            <geom name="head_collision" pos="0 0 0.08" rgba="0.5 0.1 0.1 1" size="0.018" />
                            <body name="screen" pos="0.03 0 0.105" quat="0.5 0.5 0.5 0.5">
                                <inertial diaginertia="1e-08 1e-08 1e-08" mass="0.0001" pos="0 0 0" />
                                <geom conaffinity="0" contype="0" group="1" name="screen_visual" rgba="0.2 0.2 0.2 1" size="0.12 0.07 0.001" type="box" />
                                <geom name="screen_collision" rgba="0.2 0.2 0.2 1" size="0.001" />
                            </body>
                            <body name="head_camera" pos="0.0228027 0 0.216572" quat="0.342813 -0.618449 0.618449 -0.342813">
                                <inertial diaginertia="0 0 0" mass="0" pos="0.0228027 0 0.216572" quat="0.342813 -0.618449 0.618449 -0.342813" />
                            </body>
                        </body>
                        <body name="right_torso_itb" pos="-0.055 0 0.22" quat="0.707107 0 -0.707107 0">
                            <inertial diaginertia="1e-08 1e-08 1e-08" mass="0.0001" pos="0 0 0" />
                        </body>
                        <body name="right_l1" pos="0.081 0.05 0.237" quat="0.5 -0.5 0.5 0.5">
                            <inertial diaginertia="0.0224339 0.0221624 0.0097097" mass="4.505" pos="-0.0030849 -0.026811 0.092521" quat="0.424888 0.891987 0.132364 -0.0794296" />
                            <joint axis="0 0 1" limited="true" name="right_j1" pos="0 0 0" range="-3.8095 2.2736" />
                            <geom conaffinity="0" contype="0" group="1" mesh="l1" name="right_l1_visual" rgba="0.5 0.1 0.1 1" type="mesh" />
                            <geom name="right_l1_collision" pos="0 0 0.1225" rgba="0.5 0.1 0.1 1" size="0.07" />
                            <body name="right_l2" pos="0 -0.14 0.1425" quat="0.707107 0.707107 0 0">
                                <inertial diaginertia="0.0257928 0.025506 0.00292515" mass="1.745" pos="-0.00016044 -0.014967 0.13582" quat="0.707831 -0.0524761 0.0516007 0.702537" />
                                <joint axis="0 0 1" limited="true" name="right_j2" pos="0 0 0" range="-3.0426 3.0426" />
                                <geom conaffinity="0" contype="0" group="1" mesh="l2" name="right_l2_visual" rgba="0.5 0.1 0.1 1" type="mesh" />
                                <geom name="right_l2_collision" pos="0 0 0.08" rgba="0.5 0.1 0.1 1" size="0.06 0.17" type="cylinder" />
                                <body name="right_l3" pos="0 -0.042 0.26" quat="0.707107 -0.707107 0 0">
                                    <inertial diaginertia="0.0102404 0.0096997 0.00369622" mass="2.5097" pos="-0.0048135 -0.0281 -0.084154" quat="0.902999 0.385391 -0.0880901 0.168247" />
                                    <joint axis="0 0 1" limited="true" name="right_j3" pos="0 0 0" range="-3.0439 3.0439" />
                                    <geom conaffinity="0" contype="0" group="1" mesh="l3" name="right_l3_visual" rgba="0.5 0.1 0.1 1" type="mesh" />
                                    <geom name="right_l3_collision" pos="0 -0.01 -0.12" rgba="0.5 0.1 0.1 1" size="0.06" />
                                    <body name="right_l4" pos="0 -0.125 -0.1265" quat="0.707107 0.707107 0 0">
                                        <inertial diaginertia="0.0136549 0.0135493 0.00127353" mass="1.1136" pos="-0.0018844 0.0069001 0.1341" quat="0.803612 0.031257 -0.0298334 0.593582" />
                                        <joint axis="0 0 1" limited="true" name="right_j4" pos="0 0 0" range="-2.9761 2.9761" />
                                        <geom conaffinity="0" contype="0" group="1" mesh="l4" name="right_l4_visual" rgba="0.5 0.1 0.1 1" type="mesh" />
                                        <geom name="right_l4_collision" pos="0 0 0.11" rgba="0.5 0.1 0.1 1" size="0.045 0.15" type="cylinder" />
                                        <body name="right_arm_itb" pos="-0.055 0 0.075" quat="0.707107 0 -0.707107 0">
                                            <inertial diaginertia="1e-08 1e-08 1e-08" mass="0.0001" pos="0 0 0" />
                                        </body>
                                        <body name="right_l5" pos="0 0.031 0.275" quat="0.707107 -0.707107 0 0">
                                            <inertial diaginertia="0.00474131 0.00422857 0.00190672" mass="1.5625" pos="0.0061133 -0.023697 0.076416" quat="0.404076 0.9135 0.0473125 0.00158335" />
                                            <joint axis="0 0 1" damping="0.2" limited="true" name="right_j5" pos="0 0 0" range="-2.9761 2.9761" />
                                            <geom conaffinity="0" contype="0" group="1" mesh="l5" name="right_l5_visual" rgba="0.5 0.1 0.1 1" type="mesh" />
                                            <geom name="right_l5_collision" pos="0 0 0.1" rgba="0.5 0.1 0.1 1" size="0.06" />
                                            <body name="right_hand_camera" pos="0.039552 -0.033 0.0695" quat="0.707107 0 0.707107 0">
                                                <inertial diaginertia="0 0 0" mass="0" pos="0.039552 -0.033 0.0695" quat="0.707107 0 0.707107 0" />
                                            </body>
                                            <body name="right_wrist" pos="0 0 0.10541" quat="0.707107 0.707107 0 0">
                                                <inertial diaginertia="0 0 0" mass="0" pos="0 0 0.10541" quat="0.707107 0.707107 0 0" />
                                            </body>
                                            <body name="right_l6" pos="0 -0.11 0.1053" quat="0.0616248 0.06163 -0.704416 0.704416">
                                                <camera euler="-2.7 0 0" name="wrist_cam" pos="0 0.1 0" />
                                                <inertial diaginertia="0.000360258 0.000311068 0.000214974" mass="0.3292" pos="-8.0726e-06 0.0085838 -0.0049566" quat="0.479044 0.515636 -0.513069 0.491322" />
                                                <joint axis="0 0 1" damping="0.1" limited="true" name="right_j6" pos="0 0 0" range="-4.7124 4.7124" />
                                                <geom conaffinity="0" contype="0" group="1" mesh="l6" name="right_l6_visual" rgba="0.5 0.1 0.1 1" type="mesh" />
                                                <geom name="right_l6_collision" pos="0 0.015 -0.01" rgba="0.5 0.1 0.1 1" size="0.055 0.025" type="cylinder" />
                                                <body name="right_hand" pos="0 0 0.0245" quat="0.707105 0 0 0.707108">
                                                    
                                                    <site group="1" name="ee" pos="0 0 0" rgba="0 0 1 1" size="0.01 0.01 0.01" type="sphere" />
                                                    <site group="1" name="ee_x" pos="0 0 0" quat="0.707105 0.707108 0 0 " rgba="1 0 0 1" size="0.005 .1" type="cylinder" />
                                                    <site group="1" name="ee_z" pos="0 0 0" quat="0.707105 0 0 0.707108" rgba="0 0 1 1" size="0.005 .1" type="cylinder" />
                                                    <site group="1" name="ee_y" pos="0 0 0" quat="0.707105 0 0.707108 0 " rgba="0 1 0 1" size="0.005 .1" type="cylinder" />
                                                    
                                                <body name="right_gripper_base" pos="0 0 0.025">
            <site group="1" name="ft_frame" pos="0 0 0" rgba="1 0 0 1" size="0.01 0.01 0.01" type="sphere" />
            <inertial diaginertia="3e-08 2e-08 2e-08" mass="0.3" pos="0 0 0" quat="-0.5 0.5 0.5 0.5" />
            <geom conaffinity="0" contype="0" group="1" mesh="electric_gripper_base" name="right_gripper_base_visual" quat="0 0 0.707107 0.707107" type="mesh" />
            <geom name="right_gripper_base_collision" quat="0 0 0.707107 0.707107" size="0.029 0.05" type="cylinder" />
            <body name="right_gripper" pos="0 0 0.095">
                <inertial diaginertia="0 0 0" mass="0.0001" pos="0 0 0" />
                
                <site group="1" name="grip_site" pos="0 0 -0.03" rgba="0 0 0 0" size="0.01 0.01 0.01" type="sphere" />
                
                <site group="1" name="griptip_site" pos="0 0 0" rgba="1 0 0 1" size="0.01 0.01 0.01" type="sphere" />
                <site group="1" name="lgriptip_site" pos="0 0.02 0" rgba="1 0 0 1" size="0.01 0.01 0.01" type="sphere" />
                <site group="1" name="rgriptip_site" pos="0 -0.02 0" rgba="1 0 0 1" size="0.01 0.01 0.01" type="sphere" />

                
                <site group="1" name="grip_site_cylinder" pos="0 0 0" rgba="0 0 0 0" size="0.005 10" type="cylinder" />
                
                <camera fovy="75" mode="fixed" name="eye_in_hand" pos="0 0 0" quat="0 -1 1 0" />
            </body>
            
            <body name="r_gripper_l_finger" pos="0 0.01 0.02">
                <inertial diaginertia="0.01 0.01 0.01" mass="0.02" pos="0 0 0" quat="0 0 0 -1" />
                <joint axis="0 1 0" damping="100" limited="true" name="r_gripper_l_finger_joint" pos="0 0 0" range="-0.0115 0.020833" type="slide" />
                <geom conaffinity="0" contype="0" group="1" mesh="standard_narrow" name="r_gripper_l_finger_visual" quat="0 0 0 -1" type="mesh" />
                <geom conaffinity="1" contype="0" friction="0 0 0" name="l_finger_g0" pos="0 0.01725 0.04" quat="0 0 0 -1" size="0.005 0.00675 0.0375" type="box" />
                <geom conaffinity="1" contype="0" friction="0 0 0" name="l_finger_g1" pos="-0.005 -0.003 0.0083" quat="0 0 0 -1" size="0.005 0.025 0.0085" type="box" />

                <body name="r_gripper_l_finger_tip" pos="0 0.01725 0.075">
                    <inertial diaginertia="0.01 0.01 0.01" mass="0.01" pos="0 0 0" quat="0 0 0 1" />
                    <geom conaffinity="0" contype="0" group="1" mesh="half_round_tip" name="r_gripper_l_finger_tip_visual" quat="0 0 0 1" type="mesh" />
                
                <geom conaffinity="1" contype="0" friction="2 10 0.5" name="l_fingertip_g0" pos="0 -0.0045 -0.015" quat="0 0 0 1" size="0.004 0.004 0.0185" type="box" />

                </body>
            </body>
            <body name="r_gripper_r_finger" pos="0 -0.01 0.02">
                <inertial diaginertia="0.01 0.01 0.01" mass="0.02" pos="0 0 0" />
                <joint axis="0 1 0" damping="100" limited="true" name="r_gripper_r_finger_joint" pos="0 0 0" range="-0.020833 0.0115" type="slide" />
                <geom conaffinity="0" contype="0" group="1" mesh="standard_narrow" name="r_gripper_r_finger_visual" type="mesh" />
                <geom conaffinity="1" contype="0" friction="0 0 0" name="r_finger_g0" pos="0 -0.01725 0.04" size="0.005 0.00675 0.0375" type="box" />
                <geom conaffinity="1" contype="0" friction="0 0 0" name="r_finger_g1" pos="0.005 0.003 0.0083" size="0.005 0.025 0.0085" type="box" />
                <body name="r_gripper_r_finger_tip" pos="0 -0.01725 0.075">
                    <inertial diaginertia="0.01 0.01 0.01" mass="0.01" pos="0 0 0" />
                    <geom conaffinity="0" contype="0" group="1" mesh="half_round_tip" name="r_gripper_r_finger_tip_visual" type="mesh" />
                    <geom conaffinity="1" contype="0" friction="2 10 0.5" name="r_fingertip_g0" pos="0 0.0045 -0.015" size="0.004 0.004 0.0185" type="box" />
                </body>
            </body>
        </body>
    </body>
                                            </body>
                                        </body>
                                        <body name="right_l4_2" pos="0 0 0">
                                            <inertial diaginertia="1e-08 1e-08 1e-08" mass="1e-08" pos="1e-08 1e-08 1e-08" quat="0.820473 0.339851 -0.17592 0.424708" />
                                            <geom name="right_l4_2_collision" pos="0 0.01 0.26" size="0.06" />
                                        </body>
                                    </body>
                                </body>
                                <body name="right_l2_2" pos="0 0 0">
                                    <inertial diaginertia="1e-08 1e-08 1e-08" mass="1e-08" pos="1e-08 1e-08 1e-08" quat="0.820473 0.339851 -0.17592 0.424708" />
                                    <geom name="right_l2_2_collision" pos="0 0 0.26" size="0.06" />
                                </body>
                            </body>
                            <body name="right_l1_2" pos="0 0 0">
                                <inertial diaginertia="1e-08 1e-08 1e-08" mass="1e-08" pos="1e-08 1e-08 1e-08" quat="0.820473 0.339851 -0.17592 0.424708" />
                                <geom name="right_l1_2_collision" pos="0 0 0.035" size="0.07 0.07" type="cylinder" />
                            </body>
                        </body>
                    </body>
                </body>
            </body>
        <body name="0_part0" pos="0.0 0.0 0.0" quat="1 0 0 0">
      <geom conaffinity="0" contype="0" density="0" friction="1 10 0.5" mesh="part0" name="0_part0-0" pos="0.0 0.0 0.0" rgba="0.82 0.71 0.55 1" type="mesh" />
      <site group="1" name="0_part0_ltgt_site0" pos="0.02 0 -0.02" rgba="0 0 0 0" size="0.01 0.01 0.01" type="sphere" />
      <site group="1" name="0_part0_rtgt_site0" pos="-0.02 0 -0.02" rgba="0 0 0 0" size="0.01 0.01 0.01" type="sphere" />
      <site name="0_part0_horizontal_radius_site" pos="0.0 0.0 0.0" quat="1 0 0 0" rgba="0 0 0 0" size="0.016800144133768378" />
      <site name="0_part0_top_site" pos="0.0 0.0 0.16785563708678283" quat="1 0 0 0" rgba="0 0 0 0" size="0.016800144133768378" />
      <site name="0_part0_bottom_site" pos="0.0 0.0 -0.16785563708678283" quat="1 0 0 0" rgba="0 0 0 0" size="0.016800144133768378" />
      <site name="0_part0_corner_site8" pos="-0.02663028646967926 0.02663028646967926 0.16785563708678283" quat="1 0 0 0" rgba="0 0 0 0" size="0.016800144133768378" />
      <site name="0_part0_corner_site7" pos="0.02663028646967926 0.02663028646967926 0.16785563708678283" quat="1 0 0 0" rgba="0 0 0 0" size="0.016800144133768378" />
      <site name="0_part0_corner_site6" pos="0.02663028646967926 -0.02663028646967926 0.16785563708678283" quat="1 0 0 0" rgba="0 0 0 0" size="0.016800144133768378" />
      <site name="0_part0_corner_site5" pos="-0.02663028646967926 -0.02663028646967926 0.16785563708678283" quat="1 0 0 0" rgba="0 0 0 0" size="0.016800144133768378" />
      <site name="0_part0_corner_site4" pos="-0.02663028646967926 0.02663028646967926 -0.16785563708678283" quat="1 0 0 0" rgba="0 0 0 0" size="0.016800144133768378" />
      <site name="0_part0_corner_site3" pos="0.02663028646967926 0.02663028646967926 -0.16785563708678283" quat="1 0 0 0" rgba="0 0 0 0" size="0.016800144133768378" />
      <site name="0_part0_corner_site2" pos="0.02663028646967926 -0.02663028646967926 -0.16785563708678283" quat="1 0 0 0" rgba="0 0 0 0" size="0.016800144133768378" />
      <site name="0_part0_corner_site1" pos="-0.02663028646967926 -0.02663028646967926 -0.16785563708678283" quat="1 0 0 0" rgba="0 0 0 0" size="0.016800144133768378" />
      <site name="leg-top,,conn_site0" pos="0 0 0.165" quat="0 0 1 0" rgba="0.9019 0.0980 0.2941 0.3" size="0.016800144133768378" />
      <geom density="50" friction="1 10 0.5" name="noviz_collision_0_part0_0" pos="0.0 0.0 0.0771358" quat="1 0 0 0" rgba="0 0 0 0" size="0.02 0.090748" solref="0.001 1" type="cylinder" />
      <geom density="50" friction="1 10 0.5" name="noviz_collision_0_part0_1" pos="0.0 0.0 -0.0771358" quat="1 0 0 0" rgba="0 0 0 0" size="0.02 0.093" solref="0.001 1" type="cylinder" />
    <site name="0_part0" pos="0 0 0" rgba="1 0 0 0" size="0.002 0.002 0.002" type="sphere" /><joint damping="0.0001" name="0_part0" type="free" /></body>
    <body name="4_part4" pos="-0.19870370474214546 0.19870368374196531 0.13643401251069334" quat="1 0 0 0">
      <geom conaffinity="0" contype="0" density="0" friction="1 10 0.5" mesh="part4" name="4_part4-0" pos="0.0 0.0 0.0" rgba="0.82 0.71 0.55 1" type="mesh" />
      <site name="4_part4_horizontal_radius_site" pos="0.0 0.0 0.0" quat="1 0 0 0" rgba="0 0 0 0" size="0.016800144133768378" />
      <site name="4_part4_top_site" pos="0.0 0.0 0.03774280480750086" quat="1 0 0 0" rgba="0 0 0 0" size="0.016800144133768378" />
      <site name="4_part4_bottom_site" pos="0.0 0.0 -0.03774280480750086" quat="1 0 0 0" rgba="0 0 0 0" size="0.016800144133768378" />
      <site name="4_part4_right_site" pos="0 0.23137183701242006 0.0" quat="1 0 0 0" rgba="0 0 0 0" size="0.016800144133768378" />
      <site name="4_part4_left_site" pos="0 -0.23137183701242006 0.0" quat="1 0 0 0" rgba="0 0 0 0" size="0.016800144133768378" />
      <site name="4_part4_corner_site8" pos="-0.23137183701242006 0.23137185801260024 0.03774280480750086" quat="1 0 0 0" rgba="0 0 0 0" size="0.016800144133768378" />
      <site name="4_part4_corner_site7" pos="0.23137183701242006 0.23137185801260024 0.03774280480750086" quat="1 0 0 0" rgba="0 0 0 0" size="0.016800144133768378" />
      <site name="4_part4_corner_site6" pos="0.23137183701242006 -0.23137185801260024 0.03774280480750086" quat="1 0 0 0" rgba="0 0 0 0" size="0.016800144133768378" />
      <site name="4_part4_corner_site5" pos="-0.23137183701242006 -0.23137185801260024 0.03774280480750086" quat="1 0 0 0" rgba="0 0 0 0" size="0.016800144133768378" />
      <site name="4_part4_corner_site4" pos="-0.23137183701242006 0.23137185801260024 -0.03774280480750086" quat="1 0 0 0" rgba="0 0 0 0" size="0.016800144133768378" />
      <site name="4_part4_corner_site3" pos="0.23137183701242006 0.23137185801260024 -0.03774280480750086" quat="1 0 0 0" rgba="0 0 0 0" size="0.016800144133768378" />
      <site name="4_part4_corner_site2" pos="0.23137183701242006 -0.23137185801260024 -0.03774280480750086" quat="1 0 0 0" rgba="0 0 0 0" size="0.016800144133768378" />
      <site name="4_part4_corner_site1" pos="-0.23137183701242006 -0.23137185801260024 -0.03774280480750086" quat="1 0 0 0" rgba="0 0 0 0" size="0.016800144133768378" />
      <site name="top-leg,,conn_site4" pos="0.198 0.198 -0.00" quat="0 0 1 0" rgba="0.9019 0.0980 0.2941 0.3" size="0.01679342264788419" />
      <site name="top-leg,,conn_site3" pos="0.198 -0.198 -0.00" quat="0 0 1 0" rgba="0.9019 0.0980 0.2941 0.3" size="0.016800144133768374" />
      <site name="top-leg,,conn_site2" pos="-0.198 -0.198 -0.00" quat="0 0 1 0" rgba="0.9019 0.0980 0.2941 0.3" size="0.016800144133768374" />
      <site name="top-leg,,conn_site1" pos="-0.198 0.198 -0.00" quat="0 0 1 0" rgba="0.9019 0.0980 0.2941 0.3" size="0.016800144133768374" />

      <geom density="50" friction="1 10 0.5" name="noviz_collision_4_part4_0" pos="-0.198 0.168 -0.016" quat="1 0 0 0" rgba="0 0 0 0" size="0.0115 0.0002 0.0485" solref="0.001 1" type="box" />
      <geom density="50" friction="1 10 0.5" name="noviz_collision_4_part4_1" pos="-0.198 0.228 -0.016" quat="1 0 0 0" rgba="0 0 0 0" size="0.0115 0.0002 0.0485" solref="0.001 1" type="box" />
      <geom density="50" friction="1 10 0.5" name="noviz_collision_4_part4_2" pos="-0.219 0.177 -0.016" quat="0.9238796 0 0 -0.3826834" rgba="0 0 0 0" size="0.0115 0.0002 0.0485" solref="0.001 1" type="box" />
      <geom density="50" friction="1 10 0.5" name="noviz_collision_4_part4_3" pos="-0.168 0.198 -0.016" quat="0.7071067 0 0 -0.7071068" rgba="0 0 0 0" size="0.0115 0.0002 0.0485" solref="0.001 1" type="box" />
      <geom density="50" friction="1 10 0.5" name="noviz_collision_4_part4_4" pos="-0.228 0.198 -0.016" quat="0.7071067 0 0 -0.7071068" rgba="0 0 0 0" size="0.0115 0.0002 0.0485" solref="0.001 1" type="box" />
      <geom density="50" friction="1 10 0.5" name="noviz_collision_4_part4_5" pos="-0.177 0.219 -0.016" quat="0.9238796 0 0 -0.3826834" rgba="0 0 0 0" size="0.0115 0.0002 0.0485" solref="0.001 1" type="box" />
      <geom density="50" friction="1 10 0.5" name="noviz_collision_4_part4_6" pos="-0.219 0.219 -0.016" quat="0.9238796 0 0 0.3826834" rgba="0 0 0 0" size="0.0115 0.0002 0.0485" solref="0.001 1" type="box" />
      <geom density="50" friction="1 10 0.5" name="noviz_collision_4_part4_7" pos="-0.177 0.177 -0.016" quat="0.9238796 0 0 0.3826834" rgba="0 0 0 0" size="0.0115 0.0002 0.0485" solref="0.001 1" type="box" />

      <geom density="50" friction="1 10 0.5" name="noviz_collision_4_part4_8" pos="0.198 0.168 -0.016" quat="1 0 0 0" rgba="0 0 0 0" size="0.0115 0.0002 0.0485" solref="0.001 1" type="box" />
      <geom density="50" friction="1 10 0.5" name="noviz_collision_4_part4_9" pos="0.198 0.228 -0.016" quat="1 0 0 0" rgba="0 0 0 0" size="0.0115 0.0002 0.0485" solref="0.001 1" type="box" />
      <geom density="50" friction="1 10 0.5" name="noviz_collision_4_part4_10" pos="0.177 0.177 -0.016" quat="0.9238796 0 0 -0.3826834" rgba="0 0 0 0" size="0.0115 0.0002 0.0485" solref="0.001 1" type="box" />
      <geom density="50" friction="1 10 0.5" name="noviz_collision_4_part4_11" pos="0.228 0.198 -0.016" quat="0.7071067 0 0 -0.7071068" rgba="0 0 0 0" size="0.0115 0.0002 0.0485" solref="0.001 1" type="box" />
      <geom density="50" friction="1 10 0.5" name="noviz_collision_4_part4_12" pos="0.168 0.198 -0.016" quat="0.7071067 0 0 -0.7071068" rgba="0 0 0 0" size="0.0115 0.0002 0.0485" solref="0.001 1" type="box" />
      <geom density="50" friction="1 10 0.5" name="noviz_collision_4_part4_13" pos="0.219 0.219 -0.016" quat="0.9238796 0 0 -0.3826834" rgba="0 0 0 0" size="0.0115 0.0002 0.0485" solref="0.001 1" type="box" />
      <geom density="50" friction="1 10 0.5" name="noviz_collision_4_part4_14" pos="0.177 0.219 -0.016" quat="0.9238796 0 0 0.3826834" rgba="0 0 0 0" size="0.0115 0.0002 0.0485" solref="0.001 1" type="box" />
      <geom density="50" friction="1 10 0.5" name="noviz_collision_4_part4_15" pos="0.219 0.177 -0.016" quat="0.9238796 0 0 0.3826834" rgba="0 0 0 0" size="0.0115 0.0002 0.0485" solref="0.001 1" type="box" />

      <geom density="50" friction="1 10 0.5" name="noviz_collision_4_part4_16" pos="0.198 -0.228 -0.016" quat="1 0 0 0" rgba="0 0 0 0" size="0.0115 0.0002 0.0485" solref="0.001 1" type="box" />
      <geom density="50" friction="1 10 0.5" name="noviz_collision_4_part4_17" pos="0.198 -0.170 -0.016" quat="1 0 0 0" rgba="0 0 0 0" size="0.0115 0.0002 0.0485" solref="0.001 1" type="box" />
      <geom density="50" friction="1 10 0.5" name="noviz_collision_4_part4_18" pos="0.228 -0.198 -0.016" quat="0.7071067 0 0 -0.7071068" rgba="0 0 0 0" size="0.0115 0.0002 0.0485" solref="0.001 1" type="box" />
      <geom density="50" friction="1 10 0.5" name="noviz_collision_4_part4_19" pos="0.170 -0.198 -0.016" quat="0.7071067 0 0 -0.7071068" rgba="0 0 0 0" size="0.0115 0.0002 0.0485" solref="0.001 1" type="box" />
      <geom density="50" friction="1 10 0.5" name="noviz_collision_4_part4_20" pos="0.219 -0.219 -0.016" quat="0.9238796 0 0 0.3826834" rgba="0 0 0 0" size="0.0115 0.0002 0.0485" solref="0.001 1" type="box" />
      <geom density="50" friction="1 10 0.5" name="noviz_collision_4_part4_21" pos="0.219 -0.177 -0.016" quat="0.9238796 0 0 -0.3826834" rgba="0 0 0 0" size="0.0115 0.0002 0.0485" solref="0.001 1" type="box" />
      <geom density="50" friction="1 10 0.5" name="noviz_collision_4_part4_22" pos="0.177 -0.219 -0.016" quat="0.9238796 0 0 -0.3826834" rgba="0 0 0 0" size="0.0115 0.0002 0.0485" solref="0.001 1" type="box" />
      <geom density="50" friction="1 10 0.5" name="noviz_collision_4_part4_23" pos="0.177 -0.177 -0.016" quat="0.9238796 0 0 0.3826834" rgba="0 0 0 0" size="0.0115 0.0002 0.0485" solref="0.001 1" type="box" />

      <geom density="50" friction="1 10 0.5" name="noviz_collision_4_part4_24" pos="-0.219 -0.177 -0.016" quat="0.9238796 0 0 0.3826834" rgba="0 0 0 0" size="0.0115 0.0002 0.0485" solref="0.001 1" type="box" />
      <geom density="50" friction="1 10 0.5" name="noviz_collision_4_part4_25" pos="-0.198 -0.170 -0.016" quat="1 0 0 0" rgba="0 0 0 0" size="0.0115 0.0002 0.0485" solref="0.001 1" type="box" />
      <geom density="50" friction="1 10 0.5" name="noviz_collision_4_part4_26" pos="-0.198 -0.228 -0.016" quat="1 0 0 0" rgba="0 0 0 0" size="0.0115 0.0002 0.0485" solref="0.001 1" type="box" />
      <geom density="50" friction="1 10 0.5" name="noviz_collision_4_part4_27" pos="-0.170 -0.198 -0.016" quat="0.7071067 0 0 -0.7071068" rgba="0 0 0 0" size="0.0115 0.0002 0.0485" solref="0.001 1" type="box" />
      <geom density="50" friction="1 10 0.5" name="noviz_collision_4_part4_28" pos="-0.228 -0.198 -0.016" quat="0.7071067 0 0 -0.7071068" rgba="0 0 0 0" size="0.0115 0.0002 0.0485" solref="0.001 1" type="box" />
      <geom density="50" friction="1 10 0.5" name="noviz_collision_4_part4_29" pos="-0.177 -0.219 -0.016" quat="0.9238796 0 0 0.3826834" rgba="0 0 0 0" size="0.0115 0.0002 0.0485" solref="0.001 1" type="box" />
      <geom density="50" friction="1 10 0.5" name="noviz_collision_4_part4_30" pos="-0.219 -0.219 -0.016" quat="0.9238796 0 0 -0.3826834" rgba="0 0 0 0" size="0.0115 0.0002 0.0485" solref="0.001 1" type="box" />
      <geom density="50" friction="1 10 0.5" name="noviz_collision_4_part4_31" pos="-0.177 -0.177 -0.016" quat="0.9238796 0 0 -0.3826834" rgba="0 0 0 0" size="0.0115 0.0002 0.0485" solref="0.001 1" type="box" />

      <geom density="50" friction="1 10 0.5" name="noviz_collision_4_part4_32" pos="0.0 0.0 0.036" quat="1 0 0 0" rgba="0 0 0 0" size="0.230 0.230 0.003" solref="0.001 1" type="box" />
      <geom density="50" friction="1 10 0.5" name="noviz_collision_4_part4_33" pos="0 -0.223 0.011" quat="1 0 0 0" rgba="0 0 0 0" size="0.23 0.0002 0.026" solref="0.001 1" type="box" />
      <geom density="50" friction="1 10 0.5" name="noviz_collision_4_part4_34" pos="0 0.223 0.011" quat="1 0 0 0" rgba="0 0 0 0" size="0.23 0.0002 0.026" solref="0.001 1" type="box" />
      <geom density="50" friction="1 10 0.5" name="noviz_collision_4_part4_35" pos="0.223 0 0.011" quat="0.7071067 0 0 -0.7071068" rgba="0 0 0 0" size="0.23 0.0002 0.026" solref="0.001 1" type="box" />
      <geom density="50" friction="1 10 0.5" name="noviz_collision_4_part4_36" pos="-0.223 0 0.011" quat="0.7071067 0 0 -0.7071068" rgba="0 0 0 0" size="0.23 0.0002 0.026" solref="0.001 1" type="box" />

      <geom density="50" friction="1 10 0.5" name="noviz_collision_4_part4_37" pos="-0.198 -0.198 0.01" quat="1 0 0 0" rgba="0 0 0 0" size="0.028 0.01" solref="0.001 1" type="cylinder" />
      <geom density="50" friction="1 10 0.5" name="noviz_collision_4_part4_38" pos="-0.198 0.198 0.01" quat="1 0 0 0" rgba="0 0 0 0" size="0.028 0.01" solref="0.001 1" type="cylinder" />
      <geom density="50" friction="1 10 0.5" name="noviz_collision_4_part4_39" pos="0.198 -0.198 0.01" quat="1 0 0 0" rgba="0 0 0 0" size="0.028 0.01" solref="0.001 1" type="cylinder" />
      <geom density="50" friction="1 10 0.5" name="noviz_collision_4_part4_40" pos="0.198 0.198 0.01" quat="1 0 0 0" rgba="0 0 0 0" size="0.028 0.01" solref="0.001 1" type="cylinder" />
    <site name="4_part4" pos="0 0 0" rgba="1 0 0 0" size="0.002 0.002 0.002" type="sphere" /><joint damping="0.0001" name="4_part4" type="free" /></body>
    <body name="3_part3" pos="-0.39740740948429093 0.0 0.0" quat="1 0 0 0">
      <geom conaffinity="0" contype="0" density="0" friction="1 10 0.5" mesh="part3" name="3_part3-0" pos="0.0 0.0 0.0" rgba="0.82 0.71 0.55 1" type="mesh" />
      <site group="1" name="3_part3_ltgt_site0" pos="0.02 0 -0.02" rgba="0 0 0 0" size="0.01 0.01 0.01" type="sphere" />
      <site group="1" name="3_part3_rtgt_site0" pos="-0.02 0 -0.02" rgba="0 0 0 0" size="0.01 0.01 0.01" type="sphere" />
      <site name="3_part3_horizontal_radius_site" pos="0.0 0.0 0.0" quat="1 0 0 0" rgba="0 0 0 0" size="0.016800144133768378" />
      <site name="3_part3_top_site" pos="0.0 0.0 0.16785563708678283" quat="1 0 0 0" rgba="0 0 0 0" size="0.016800144133768378" />
      <site name="3_part3_bottom_site" pos="0.0 0.0 -0.16785563708678283" quat="1 0 0 0" rgba="0 0 0 0" size="0.016800144133768378" />
      <site name="3_part3_corner_site8" pos="-0.02663028646967926 0.02663028646967926 0.16785563708678283" quat="1 0 0 0" rgba="0 0 0 0" size="0.016800144133768378" />
      <site name="3_part3_corner_site7" pos="0.02663028646967926 0.02663028646967926 0.16785563708678283" quat="1 0 0 0" rgba="0 0 0 0" size="0.016800144133768378" />
      <site name="3_part3_corner_site6" pos="0.02663028646967926 -0.02663028646967926 0.16785563708678283" quat="1 0 0 0" rgba="0 0 0 0" size="0.016800144133768378" />
      <site name="3_part3_corner_site5" pos="-0.02663028646967926 -0.02663028646967926 0.16785563708678283" quat="1 0 0 0" rgba="0 0 0 0" size="0.016800144133768378" />
      <site name="3_part3_corner_site4" pos="-0.02663028646967926 0.02663028646967926 -0.16785563708678283" quat="1 0 0 0" rgba="0 0 0 0" size="0.016800144133768378" />
      <site name="3_part3_corner_site3" pos="0.02663028646967926 0.02663028646967926 -0.16785563708678283" quat="1 0 0 0" rgba="0 0 0 0" size="0.016800144133768378" />
      <site name="3_part3_corner_site2" pos="0.02663028646967926 -0.02663028646967926 -0.16785563708678283" quat="1 0 0 0" rgba="0 0 0 0" size="0.016800144133768378" />
      <site name="3_part3_corner_site1" pos="-0.02663028646967926 -0.02663028646967926 -0.16785563708678283" quat="1 0 0 0" rgba="0 0 0 0" size="0.016800144133768378" />
      <site name="leg-top,,conn_site3" pos="0 0 0.165" quat="0 0 1 0" rgba="0.9019 0.0980 0.2941 0.3" size="0.016800144133768374" />
      <geom density="50" friction="1 10 0.5" name="noviz_collision_3_part3_0" pos="0.0 0.0 0.0771358" quat="1 0 0 0" rgba="0 0 0 0" size="0.02 0.090748" solref="0.001 1" type="cylinder" />
      <geom density="50" friction="1 10 0.5" name="noviz_collision_3_part3_1" pos="0.0 0.0 -0.0771358" quat="1 0 0 0" rgba="0 0 0 0" size="0.02 0.093" solref="0.001 1" type="cylinder" />
    <site name="3_part3" pos="0 0 0" rgba="1 0 0 0" size="0.002 0.002 0.002" type="sphere" /><joint damping="0.0001" name="3_part3" type="free" /></body>
    <body name="2_part2" pos="0.0 0.39740740948429093 -0.0" quat="1 0 0 0">
      <geom conaffinity="0" contype="0" density="0" friction="1 10 0.5" mesh="part2" name="2_part2-0" pos="0.0 0.0 0.0" rgba="0.82 0.71 0.55 1" type="mesh" />
      <site group="1" name="2_part2_ltgt_site0" pos="0.02 0 -0.02" rgba="0 0 0 0" size="0.01 0.01 0.01" type="sphere" />
      <site group="1" name="2_part2_rtgt_site0" pos="-0.02 0 -0.02" rgba="0 0 0 0" size="0.01 0.01 0.01" type="sphere" />
      <site name="2_part2_horizontal_radius_site" pos="0.0 0.0 0.0" quat="1 0 0 0" rgba="0 0 0 0" size="0.016800144133768378" />
      <site name="2_part2_top_site" pos="0.0 0.0 0.16785563708678283" quat="1 0 0 0" rgba="0 0 0 0" size="0.016800144133768378" />
      <site name="2_part2_bottom_site" pos="0.0 0.0 -0.16785563708678283" quat="1 0 0 0" rgba="0 0 0 0" size="0.016800144133768378" />
      <site name="2_part2_corner_site8" pos="-0.02663028646967926 0.02663028646967926 0.16785563708678283" quat="1 0 0 0" rgba="0 0 0 0" size="0.016800144133768378" />
      <site name="2_part2_corner_site7" pos="0.02663028646967926 0.02663028646967926 0.16785563708678283" quat="1 0 0 0" rgba="0 0 0 0" size="0.016800144133768378" />
      <site name="2_part2_corner_site6" pos="0.02663028646967926 -0.02663028646967926 0.16785563708678283" quat="1 0 0 0" rgba="0 0 0 0" size="0.016800144133768378" />
      <site name="2_part2_corner_site5" pos="-0.02663028646967926 -0.02663028646967926 0.16785563708678283" quat="1 0 0 0" rgba="0 0 0 0" size="0.016800144133768378" />
      <site name="2_part2_corner_site4" pos="-0.02663028646967926 0.02663028646967926 -0.16785563708678283" quat="1 0 0 0" rgba="0 0 0 0" size="0.016800144133768378" />
      <site name="2_part2_corner_site3" pos="0.02663028646967926 0.02663028646967926 -0.16785563708678283" quat="1 0 0 0" rgba="0 0 0 0" size="0.016800144133768378" />
      <site name="2_part2_corner_site2" pos="0.02663028646967926 -0.02663028646967926 -0.16785563708678283" quat="1 0 0 0" rgba="0 0 0 0" size="0.016800144133768378" />
      <site name="2_part2_corner_site1" pos="-0.02663028646967926 -0.02663028646967926 -0.16785563708678283" quat="1 0 0 0" rgba="0 0 0 0" size="0.016800144133768378" />
      <site name="leg-top,,conn_site2" pos="0 0 0.165" quat="0 0 1 0" rgba="0.9019 0.0980 0.2941 0.3" size="0.016800144133768374" />
      <geom density="20" friction="1 10 0.5" name="noviz_collision_2_part2_0" pos="0.0 0.0 0.0771358" quat="1 0 0 0" rgba="0 0 0 0" size="0.02 0.090748" solref="0.001 1" type="cylinder" />
      <geom density="20" friction="1 10 0.5" name="noviz_collision_2_part2_1" pos="0.0 0.0 -0.0771358" quat="1 0 0 0" rgba="0 0 0 0" size="0.02 0.093" solref="0.001 1" type="cylinder" />
    <site name="2_part2" pos="0 0 0" rgba="1 0 0 0" size="0.002 0.002 0.002" type="sphere" /><joint damping="0.0001" name="2_part2" type="free" /></body>
    <body name="1_part1" pos="-0.39740740948429093 0.39740740948429093 -0.0" quat="1 0 0 0">
      <geom conaffinity="0" contype="0" density="01" friction="1 10 0.5" mesh="part1" name="1_part1-0" pos="0.0 0.0 0.0" rgba="0.82 0.71 0.55 1" type="mesh" />
      <site group="1" name="1_part1_ltgt_site0" pos="0.02 0 -0.02" rgba="0 0 0 0" size="0.01 0.01 0.01" type="sphere" />
      <site group="1" name="1_part1_rtgt_site0" pos="-0.02 0 -0.02" rgba="0 0 0 0" size="0.01 0.01 0.01" type="sphere" />
      <site name="1_part1_horizontal_radius_site" pos="0.0 0.0 0.0" quat="1 0 0 0" rgba="0 0 0 0" size="0.016800144133768378" />
      <site name="1_part1_top_site" pos="0.0 0.0 0.16785563708678283" quat="1 0 0 0" rgba="0 0 0 0" size="0.016800144133768378" />
      <site name="1_part1_bottom_site" pos="0.0 0.0 -0.16785563708678283" quat="1 0 0 0" rgba="0 0 0 0" size="0.016800144133768378" />
      <site name="1_part1_corner_site8" pos="-0.02663028646967926 0.02663028646967926 0.16785563708678283" quat="1 0 0 0" rgba="0 0 0 0" size="0.016800144133768378" />
      <site name="1_part1_corner_site7" pos="0.02663028646967926 0.02663028646967926 0.16785563708678283" quat="1 0 0 0" rgba="0 0 0 0" size="0.016800144133768378" />
      <site name="1_part1_corner_site6" pos="0.02663028646967926 -0.02663028646967926 0.16785563708678283" quat="1 0 0 0" rgba="0 0 0 0" size="0.016800144133768378" />
      <site name="1_part1_corner_site5" pos="-0.02663028646967926 -0.02663028646967926 0.16785563708678283" quat="1 0 0 0" rgba="0 0 0 0" size="0.016800144133768378" />
      <site name="1_part1_corner_site4" pos="-0.02663028646967926 0.02663028646967926 -0.16785563708678283" quat="1 0 0 0" rgba="0 0 0 0" size="0.016800144133768378" />
      <site name="1_part1_corner_site3" pos="0.02663028646967926 0.02663028646967926 -0.16785563708678283" quat="1 0 0 0" rgba="0 0 0 0" size="0.016800144133768378" />
      <site name="1_part1_corner_site2" pos="0.02663028646967926 -0.02663028646967926 -0.16785563708678283" quat="1 0 0 0" rgba="0 0 0 0" size="0.016800144133768378" />
      <site name="1_part1_corner_site1" pos="-0.02663028646967926 -0.02663028646967926 -0.16785563708678283" quat="1 0 0 0" rgba="0 0 0 0" size="0.016800144133768378" />
      <site name="leg-top,,conn_site1" pos="0 0 0.165" quat="0 0 1 0" rgba="0.9019 0.0980 0.2941 0.3" size="0.016800144133768374" />
      <geom density="50" friction="1 10 0.5" name="noviz_collision_1_part1_0" pos="0.0 0.0 0.0771358" quat="1 0 0 0" rgba="0 0 0 0" size="0.02 0.090748" solref="0.001 1" type="cylinder" />
      <geom density="50" friction="1 10 0.5" name="noviz_collision_1_part1_1" pos="0.0 0.0 -0.0771358" quat="1 0 0 0" rgba="0 0 0 0" size="0.02 0.093" solref="0.001 1" type="cylinder" />
    <site name="1_part1" pos="0 0 0" rgba="1 0 0 0" size="0.002 0.002 0.002" type="sphere" /><joint damping="0.0001" name="1_part1" type="free" /></body>
  </worldbody>

  <equality>
  <weld active="false" body1="0_part0" body2="4_part4" solimp="1 1 0.5" solref="0.01 0.3" />
    <weld active="false" body1="1_part1" body2="4_part4" solimp="1 1 0.5" solref="0.01 0.3" />
    <weld active="false" body1="2_part2" body2="4_part4" solimp="1 1 0.5" solref="0.01 0.3" />
    <weld active="false" body1="3_part3" body2="4_part4" solimp="1 1 0.5" solref="0.01 0.3" />
  </equality>
<sensor><force name="force_ee" site="ft_frame" />
        <torque name="torque_ee" site="ft_frame" />
    </sensor><contact /><default /></mujoco>